2024-12-08 00:23:51,516 ERROR: Exception on /users/register [POST] [in /usr/local/lib/python3.9/site-packages/flask/app.py:875]
Traceback (most recent call last):
  File "/usr/local/lib/python3.9/site-packages/sqlalchemy/engine/base.py", line 1967, in _exec_single_context
    self.dialect.do_execute(
  File "/usr/local/lib/python3.9/site-packages/sqlalchemy/engine/default.py", line 941, in do_execute
    cursor.execute(statement, parameters)
  File "/usr/local/lib/python3.9/site-packages/pymysql/cursors.py", line 153, in execute
    result = self._query(query)
  File "/usr/local/lib/python3.9/site-packages/pymysql/cursors.py", line 322, in _query
    conn.query(q)
  File "/usr/local/lib/python3.9/site-packages/pymysql/connections.py", line 563, in query
    self._affected_rows = self._read_query_result(unbuffered=unbuffered)
  File "/usr/local/lib/python3.9/site-packages/pymysql/connections.py", line 825, in _read_query_result
    result.read()
  File "/usr/local/lib/python3.9/site-packages/pymysql/connections.py", line 1199, in read
    first_packet = self.connection._read_packet()
  File "/usr/local/lib/python3.9/site-packages/pymysql/connections.py", line 775, in _read_packet
    packet.raise_for_error()
  File "/usr/local/lib/python3.9/site-packages/pymysql/protocol.py", line 219, in raise_for_error
    err.raise_mysql_exception(self._data)
  File "/usr/local/lib/python3.9/site-packages/pymysql/err.py", line 150, in raise_mysql_exception
    raise errorclass(errno, errval)
pymysql.err.IntegrityError: (1062, "Duplicate entry 'f1ade4ac-cead-47fc-95f6-089d3b6166f1' for key 'users.PRIMARY'")

The above exception was the direct cause of the following exception:

Traceback (most recent call last):
  File "/usr/local/lib/python3.9/site-packages/flask/app.py", line 1511, in wsgi_app
    response = self.full_dispatch_request()
  File "/usr/local/lib/python3.9/site-packages/flask/app.py", line 919, in full_dispatch_request
    rv = self.handle_user_exception(e)
  File "/usr/local/lib/python3.9/site-packages/flask/app.py", line 917, in full_dispatch_request
    rv = self.dispatch_request()
  File "/usr/local/lib/python3.9/site-packages/flask/app.py", line 902, in dispatch_request
    return self.ensure_sync(self.view_functions[rule.endpoint])(**view_args)  # type: ignore[no-any-return]
  File "/app/app/routes.py", line 39, in register
    db.session.commit()
  File "/usr/local/lib/python3.9/site-packages/sqlalchemy/orm/scoping.py", line 597, in commit
    return self._proxied.commit()
  File "/usr/local/lib/python3.9/site-packages/sqlalchemy/orm/session.py", line 2028, in commit
    trans.commit(_to_root=True)
  File "<string>", line 2, in commit
  File "/usr/local/lib/python3.9/site-packages/sqlalchemy/orm/state_changes.py", line 139, in _go
    ret_value = fn(self, *arg, **kw)
  File "/usr/local/lib/python3.9/site-packages/sqlalchemy/orm/session.py", line 1313, in commit
    self._prepare_impl()
  File "<string>", line 2, in _prepare_impl
  File "/usr/local/lib/python3.9/site-packages/sqlalchemy/orm/state_changes.py", line 139, in _go
    ret_value = fn(self, *arg, **kw)
  File "/usr/local/lib/python3.9/site-packages/sqlalchemy/orm/session.py", line 1288, in _prepare_impl
    self.session.flush()
  File "/usr/local/lib/python3.9/site-packages/sqlalchemy/orm/session.py", line 4352, in flush
    self._flush(objects)
  File "/usr/local/lib/python3.9/site-packages/sqlalchemy/orm/session.py", line 4488, in _flush
    transaction.rollback(_capture_exception=True)
  File "/usr/local/lib/python3.9/site-packages/sqlalchemy/util/langhelpers.py", line 146, in __exit__
    raise exc_value.with_traceback(exc_tb)
  File "/usr/local/lib/python3.9/site-packages/sqlalchemy/orm/session.py", line 4448, in _flush
    flush_context.execute()
  File "/usr/local/lib/python3.9/site-packages/sqlalchemy/orm/unitofwork.py", line 466, in execute
    rec.execute(self)
  File "/usr/local/lib/python3.9/site-packages/sqlalchemy/orm/unitofwork.py", line 642, in execute
    util.preloaded.orm_persistence.save_obj(
  File "/usr/local/lib/python3.9/site-packages/sqlalchemy/orm/persistence.py", line 93, in save_obj
    _emit_insert_statements(
  File "/usr/local/lib/python3.9/site-packages/sqlalchemy/orm/persistence.py", line 1233, in _emit_insert_statements
    result = connection.execute(
  File "/usr/local/lib/python3.9/site-packages/sqlalchemy/engine/base.py", line 1418, in execute
    return meth(
  File "/usr/local/lib/python3.9/site-packages/sqlalchemy/sql/elements.py", line 515, in _execute_on_connection
    return connection._execute_clauseelement(
  File "/usr/local/lib/python3.9/site-packages/sqlalchemy/engine/base.py", line 1640, in _execute_clauseelement
    ret = self._execute_context(
  File "/usr/local/lib/python3.9/site-packages/sqlalchemy/engine/base.py", line 1846, in _execute_context
    return self._exec_single_context(
  File "/usr/local/lib/python3.9/site-packages/sqlalchemy/engine/base.py", line 1986, in _exec_single_context
    self._handle_dbapi_exception(
  File "/usr/local/lib/python3.9/site-packages/sqlalchemy/engine/base.py", line 2355, in _handle_dbapi_exception
    raise sqlalchemy_exception.with_traceback(exc_info[2]) from e
  File "/usr/local/lib/python3.9/site-packages/sqlalchemy/engine/base.py", line 1967, in _exec_single_context
    self.dialect.do_execute(
  File "/usr/local/lib/python3.9/site-packages/sqlalchemy/engine/default.py", line 941, in do_execute
    cursor.execute(statement, parameters)
  File "/usr/local/lib/python3.9/site-packages/pymysql/cursors.py", line 153, in execute
    result = self._query(query)
  File "/usr/local/lib/python3.9/site-packages/pymysql/cursors.py", line 322, in _query
    conn.query(q)
  File "/usr/local/lib/python3.9/site-packages/pymysql/connections.py", line 563, in query
    self._affected_rows = self._read_query_result(unbuffered=unbuffered)
  File "/usr/local/lib/python3.9/site-packages/pymysql/connections.py", line 825, in _read_query_result
    result.read()
  File "/usr/local/lib/python3.9/site-packages/pymysql/connections.py", line 1199, in read
    first_packet = self.connection._read_packet()
  File "/usr/local/lib/python3.9/site-packages/pymysql/connections.py", line 775, in _read_packet
    packet.raise_for_error()
  File "/usr/local/lib/python3.9/site-packages/pymysql/protocol.py", line 219, in raise_for_error
    err.raise_mysql_exception(self._data)
  File "/usr/local/lib/python3.9/site-packages/pymysql/err.py", line 150, in raise_mysql_exception
    raise errorclass(errno, errval)
sqlalchemy.exc.IntegrityError: (pymysql.err.IntegrityError) (1062, "Duplicate entry 'f1ade4ac-cead-47fc-95f6-089d3b6166f1' for key 'users.PRIMARY'")
[SQL: INSERT INTO users (user_id, username, password_hash, email, `role`, created_at) VALUES (%(user_id)s, %(username)s, %(password_hash)s, %(email)s, %(role)s, now())]
[parameters: {'user_id': 'f1ade4ac-cead-47fc-95f6-089d3b6166f1', 'username': 'andrea', 'password_hash': 'scrypt:32768:8:1$MFZm26KjKgjvzcDX$8da2d1f377589c8247e9a3be0f1708de38381ce9e3b67c8f9e70e42c76d23b61dfa80978d582fe383021d27eabb6a08b993a57b8510f779b2dbc1e7c2f2b6f2a', 'email': 'andrea@gmail.com', 'role': 'rider'}]
(Background on this error at: https://sqlalche.me/e/20/gkpj)
2024-12-08 00:30:44,345 INFO: Application startup [in /app/app/logger.py:19]
2024-12-08 00:31:10,757 INFO: Application startup [in /app/app/logger.py:19]
2024-12-08 00:32:16,759 INFO: Register attempt for username: andrea [in /app/app/routes.py:18]
2024-12-08 00:32:16,920 INFO: User registered successfully: andrea [in /app/app/routes.py:41]
2024-12-08 00:33:19,408 INFO: Register attempt for username: pippo [in /app/app/routes.py:18]
2024-12-08 00:33:19,556 INFO: User registered successfully: pippo [in /app/app/routes.py:41]
2024-12-08 10:30:55,779 INFO: Application startup [in /app/app/logger.py:19]
2024-12-08 10:56:40,141 INFO: Login attempt for username: andrea [in /app/app/routes.py:50]
2024-12-08 10:56:40,718 INFO: User logged in successfully: andrea [in /app/app/routes.py:64]
2024-12-08 11:04:13,599 INFO: Login attempt for username: andrea [in /app/app/routes.py:50]
2024-12-08 11:04:13,824 INFO: User logged in successfully: andrea [in /app/app/routes.py:64]
2024-12-08 11:04:44,235 INFO: Login attempt for username: andrea [in /app/app/routes.py:50]
2024-12-08 11:04:44,360 INFO: User logged in successfully: andrea [in /app/app/routes.py:64]
2024-12-08 11:04:57,116 INFO: Login attempt for username: andrea [in /app/app/routes.py:50]
2024-12-08 11:04:57,651 WARNING: Invalid credentials for username: andrea [in /app/app/routes.py:67]
2024-12-08 11:05:06,864 INFO: Login attempt for username: andrea [in /app/app/routes.py:50]
2024-12-08 11:05:06,996 INFO: User logged in successfully: andrea [in /app/app/routes.py:64]
2024-12-08 11:06:51,559 INFO: Login attempt for username: andrea_amato [in /app/app/routes.py:50]
2024-12-08 11:06:51,566 WARNING: Invalid credentials for username: andrea_amato [in /app/app/routes.py:67]
2024-12-08 11:07:48,474 INFO: Login attempt for username: andrea [in /app/app/routes.py:50]
2024-12-08 11:07:48,601 WARNING: Invalid credentials for username: andrea [in /app/app/routes.py:67]
2024-12-08 11:08:07,251 INFO: Login attempt for username: andrea [in /app/app/routes.py:50]
2024-12-08 11:08:07,390 INFO: User logged in successfully: andrea [in /app/app/routes.py:64]
2024-12-08 11:23:58,737 INFO: Application startup [in /app/app/logger.py:19]
2024-12-08 11:48:27,457 INFO: Application startup [in /app/app/logger.py:19]
2024-12-08 11:56:12,568 INFO: Fetching user by username: pippo [in /app/app/routes.py:90]
2024-12-08 11:56:12,585 INFO: User found: pippo [in /app/app/routes.py:99]
2024-12-08 12:07:02,473 INFO: Fetching user by ID: 0c3c1a7e-1e1b-4709-8320-0a1bcfeafa6d [in /app/app/routes.py:72]
2024-12-08 12:07:02,486 INFO: User found: andrea [in /app/app/routes.py:82]
2024-12-08 12:45:59,585 INFO: Login attempt for username: andrea [in /app/app/routes.py:50]
2024-12-08 12:45:59,750 INFO: User logged in successfully: andrea [in /app/app/routes.py:64]
2024-12-08 12:46:39,395 INFO: Fetching user by ID: 0c3c1a7e-1e1b-4709-8320-0a1bcfeafa6d [in /app/app/routes.py:72]
